Workbook

Sheet Start Here
A1: ACS Health Maturity Kit — Assessment Workbook
A2: Version 0.1.0 · 2026-10-29 · Andrade Consulting Services · Licensed under CC BY 4.0
A4: Purpose | B4: A free self-assessment for U.S. healthcare organizations of their maturity in three areas: License Optimization, App Modernization and Zero Trust. Questions are mapped to the HHS Healthcare and Public Health Cybersecurity Performance Goals (CPGs), the HIPAA Security Rule, NIST CSF 2.0, the CISA Zero Trust Maturity Model v2.0, NIST SP 800-218 (SSDF), ISO/IEC 19770-1 and the FinOps Framework.
A5: Who should answer | B5: The IT leader, with input from security, infrastructure, applications, procurement and clinical informatics. Answer based on evidence, not intent.
A6: How to use | B6: 1) Fill in the Profile sheet. 2) Answer every question in the three service sheets using the yellow Answer column. 3) Review the Dashboard, Priority Gaps and CPG Crosswalk sheets. 4) Use App Portfolio Triage and License-Security Map for detailed planning.
A7: Cells to edit | B7: Only yellow cells. All other values are calculated.
A8: Example | B8: If MFA protects remote access but not email or privileged accounts, answer ZT-01 with "2 - Developing".
A9: Weights | B9: 3 = critical to patient safety or data protection; 2 = important; 1 = foundational.
A10: Scoring | B10: Each answer scores 0–4. Scores are weighted averages; "N/A" and blank answers are excluded. Gap points = (4 − score) × weight and rank the Priority Gaps.
A11: Privacy | B11: Do NOT enter protected health information (PHI), passwords or network addresses in this workbook.
A12: Disclaimer | B12: This is a self-assessment aid. It is not legal, licensing or compliance advice and does not certify compliance with HIPAA or any other requirement.
A13: Report use and feedback | B13: Please tell us how you used the kit: open an "Adoption report" issue in the project repository. Usage reports help improve the kit for other organizations.
A15: Maturity scale
A16: Answer | B16: Meaning
A17: 0 - Not in place | B17: The practice does not exist.
A18: 1 - Initial | B18: Ad hoc; depends on individuals; not documented.
A19: 2 - Developing | B19: Partly implemented or documented; not applied consistently.
A20: 3 - Defined | B20: Documented and applied consistently across the organization.
A21: 4 - Optimized | B21: Measured, reviewed regularly and improved; automated where practical.
A23: Sheets
A24: Profile | B24: Organization context.
A25: License Optimization | B25: 24 questions on licensing governance, entitlements, usage, security value, cloud cost and programs.
A26: App Modernization | B26: 24 questions on portfolio visibility, lifecycle, roadmap, engineering, resilience and cloud readiness.
A27: Zero Trust | B27: 28 questions organized by the CISA Zero Trust Maturity Model pillars plus governance and readiness.
A28: Dashboard | B28: Scores by service and dimension, with charts.
A29: Priority Gaps | B29: The 20 gaps with the most gap points and the recommended action for each.
A30: CPG Crosswalk | B30: Status against each of the 20 HHS Cybersecurity Performance Goals.
A31: App Portfolio Triage | B31: Application inventory with risk scoring and a suggested disposition.
A32: License-Security Map | B32: Security capabilities included in common Microsoft licenses and whether they are deployed.
A34: Legend
A35: Input cell | B35: Yellow cells are for your answers.

Sheet Profile
A1: Organization Profile
A2: Context for interpreting the results. Do not enter PHI.
A4: Organization name
A5: State
A6: Organization type
A7: Licensed beds
A8: Workforce size (approx.)
A9: IT staff (FTE)
A10: Primary EHR
A11: Microsoft agreement
A12: Microsoft 365 plan
A13: Assessment date
A14: Assessed by (role)

Sheet License Optimization
A1: License Optimization — Maturity Questionnaire
A2: Answer each question in the yellow column using the 0–4 scale (see Start Here). Grey columns are calculated.
A4: ID | B4: Dimension | C4: Question | D4: What “4 - Optimized” looks like | E4: Evidence to review | F4: HHS CPG mapping | G4: Other references | H4: Weight | I4: Answer | J4: Notes | K4: Recommended action if gap | L4: Score | M4: Weighted score | N4: Weight applied | O4: Gap points
A5: LO-01 | B5: Governance & Ownership | C5: Is a named person accountable for software licensing, renewals and license compliance? | D5: A named software asset management (SAM) owner has defined responsibilities across procurement, IT, finance and compliance, reviewed annually by leadership. | E5: RACI or job description; SAM charter. | G5: ISO/IEC 19770-1; NIST CSF 2.0 GV.RR | H5: 2 | K5: Appoint a SAM owner and publish a RACI covering procurement, IT, finance and compliance. | L5: =IF(OR(I5="",I5="N/A"),"",VALUE(LEFT(I5,1))) | M5: =IF(L5="",0,L5*H5) | N5: =IF(L5="",0,H5) | O5: =IF(L5="",0,(4-L5)*H5)
A6: LO-02 | B6: Governance & Ownership | C6: Are licensing decisions governed by a documented policy (requests, approvals, reharvesting, retirement)? | D6: A documented policy is followed for every request, approval, reassignment and retirement of licenses, and exceptions are recorded. | E6: Licensing policy; sample approval records. | G6: ISO/IEC 19770-1; NIST CSF 2.0 GV.PO | H6: 2 | K6: Document a licensing policy and route all requests through a single approval workflow. | L6: =IF(OR(I6="",I6="N/A"),"",VALUE(LEFT(I6,1))) | M6: =IF(L6="",0,L6*H6) | N6: =IF(L6="",0,H6) | O6: =IF(L6="",0,(4-L6)*H6)
A7: LO-03 | B7: Governance & Ownership | C7: Are renewals tracked in a calendar and reviewed well before expiry? | D7: All agreements are in a renewal calendar; usage and needs are reviewed at least 120 days before each renewal. | E7: Renewal calendar; minutes of the last renewal review. | G7: FinOps Framework (Operate) | H7: 3 | K7: Build a renewal calendar and start each renewal review 120 days before expiry. | L7: =IF(OR(I7="",I7="N/A"),"",VALUE(LEFT(I7,1))) | M7: =IF(L7="",0,L7*H7) | N7: =IF(L7="",0,H7) | O7: =IF(L7="",0,(4-L7)*H7)
A8: LO-04 | B8: Governance & Ownership | C8: Is licensing cost reported to leadership with trends and per-user metrics? | D8: Leadership receives a periodic report of licensing cost, cost per user and savings achieved, and uses it in budget decisions. | E8: Latest licensing cost report. | G8: FinOps Framework (Inform); NIST CSF 2.0 GV.OV | H8: 1 | K8: Publish a quarterly licensing cost report with cost per user and savings achieved. | L8: =IF(OR(I8="",I8="N/A"),"",VALUE(LEFT(I8,1))) | M8: =IF(L8="",0,L8*H8) | N8: =IF(L8="",0,H8) | O8: =IF(L8="",0,(4-L8)*H8)
A9: LO-05 | B9: Entitlements | C9: Is there a complete, current record of all Microsoft entitlements (agreements, products, quantities, terms)? | D9: A single repository lists every agreement, product, quantity, term and true-up obligation, reconciled after each purchase. | E9: Entitlement register; agreement documents. | G9: ISO/IEC 19770-1; NIST CSF 2.0 ID.AM | H9: 3 | K9: Consolidate all agreements and order records into one entitlement register. | L9: =IF(OR(I9="",I9="N/A"),"",VALUE(LEFT(I9,1))) | M9: =IF(L9="",0,L9*H9) | N9: =IF(L9="",0,H9) | O9: =IF(L9="",0,(4-L9)*H9)
A10: LO-06 | B10: Entitlements | C10: Are entitlements reconciled against contracts and invoices at least annually? | D10: Entitlements, contracts and invoices are reconciled annually and discrepancies are resolved with the supplier. | E10: Last reconciliation record. | G10: ISO/IEC 19770-1 | H10: 2 | K10: Reconcile entitlements against contracts and invoices before each renewal. | L10: =IF(OR(I10="",I10="N/A"),"",VALUE(LEFT(I10,1))) | M10: =IF(L10="",0,L10*H10) | N10: =IF(L10="",0,H10) | O10: =IF(L10="",0,(4-L10)*H10)
A11: LO-07 | B11: Entitlements | C11: Are licenses for clinical and business applications (EHR modules, imaging, laboratory, revenue cycle) inventoried in the same repository? | D11: Clinical and business application licenses are recorded with the same detail as Microsoft licenses, including metrics and renewal dates. | E11: Entitlement register extract for clinical systems. | G11: NIST CSF 2.0 ID.AM | H11: 2 | K11: Extend the entitlement register to clinical and business application licenses. | L11: =IF(OR(I11="",I11="N/A"),"",VALUE(LEFT(I11,1))) | M11: =IF(L11="",0,L11*H11) | N11: =IF(L11="",0,H11) | O11: =IF(L11="",0,(4-L11)*H11)
A12: LO-08 | B12: Entitlements | C12: Are third-party license obligations embedded in vendor systems and medical devices (e.g., bundled Windows or SQL Server) identified? | D12: Embedded software in vendor systems and devices is identified, with responsibility for licensing and updates assigned in contracts. | E12: Vendor contracts; device software inventory. | F12: CPG-E: Vendor/Supplier Cybersecurity Requirements | G12: NIST CSF 2.0 GV.SC | H12: 1 | K12: Identify embedded software in vendor systems and assign licensing and update responsibility in contracts. | L12: =IF(OR(I12="",I12="N/A"),"",VALUE(LEFT(I12,1))) | M12: =IF(L12="",0,L12*H12) | N12: =IF(L12="",0,H12) | O12: =IF(L12="",0,(4-L12)*H12)
A13: LO-09 | B13: Deployment & Usage | C13: Is actual software deployment discovered automatically across endpoints, servers and cloud? | D13: Automated discovery covers all endpoints, servers and cloud resources and is compared with entitlements at least monthly. | E13: Discovery tool reports; coverage percentage. | F13: CPG-X: Asset Inventory | G13: NIST CSF 2.0 ID.AM | H13: 3 | K13: Deploy automated discovery and compare deployments with entitlements monthly. | L13: =IF(OR(I13="",I13="N/A"),"",VALUE(LEFT(I13,1))) | M13: =IF(L13="",0,L13*H13) | N13: =IF(L13="",0,H13) | O13: =IF(L13="",0,(4-L13)*H13)
A14: LO-10 | B14: Deployment & Usage | C14: Is the use of assigned user licenses reviewed at least quarterly? | D14: Usage reports are reviewed quarterly and inactive or underused licenses are reassigned or downgraded. | E14: Usage reports; reassignment records. | G14: FinOps Framework (Inform, Optimize) | H14: 3 | K14: Review user license activity quarterly and reassign or downgrade inactive licenses. | L14: =IF(OR(I14="",I14="N/A"),"",VALUE(LEFT(I14,1))) | M14: =IF(L14="",0,L14*H14) | N14: =IF(L14="",0,H14) | O14: =IF(L14="",0,(4-L14)*H14)
A15: LO-11 | B15: Deployment & Usage | C15: Are the accounts and licenses of departing workforce members removed and reharvested promptly? | D15: Departures trigger account disablement and license reharvesting within one business day, verified by a periodic reconciliation with HR records. | E15: Offboarding procedure; HR-to-directory reconciliation. | F15: CPG-E: Revoke Credentials for Departing Workforce Members | G15: HIPAA 45 CFR 164.308(a)(3)(ii)(C) | H15: 3 | K15: Automate offboarding from HR records to disable accounts and reharvest licenses within one business day. | L15: =IF(OR(I15="",I15="N/A"),"",VALUE(LEFT(I15,1))) | M15: =IF(L15="",0,L15*H15) | N15: =IF(L15="",0,H15) | O15: =IF(L15="",0,(4-L15)*H15)
A16: LO-12 | B16: Deployment & Usage | C16: Are licensing models for shared clinical devices and frontline staff applied correctly? | D16: Shared workstations, kiosks and frontline roles use the licensing models intended for them, reviewed when workflows change. | E16: Licensing assignment by role and device type. | G16: ISO/IEC 19770-1 | H16: 1 | K16: Map roles and shared devices to the appropriate licensing models and correct over- or under-licensing. | L16: =IF(OR(I16="",I16="N/A"),"",VALUE(LEFT(I16,1))) | M16: =IF(L16="",0,L16*H16) | N16: =IF(L16="",0,H16) | O16: =IF(L16="",0,(4-L16)*H16)
A17: LO-13 | B17: Security Value Realization | C17: Does the organization know which security capabilities are already included in its current licenses? | D17: A current map shows every licensed security capability (identity, endpoint, email, data protection, logging) and whether it is deployed. | E17: License-to-security capability map (see sheet License-Security Map). | F17: CPG-E: Multifactor Authentication; CPG-E: Email Security; CPG-E: Strong Encryption | G17: NIST CSF 2.0 ID.AM, PR.AA | H17: 3 | K17: Complete the License-Security Map sheet and confirm it with your licensing partner. | L17: =IF(OR(I17="",I17="N/A"),"",VALUE(LEFT(I17,1))) | M17: =IF(L17="",0,L17*H17) | N17: =IF(L17="",0,H17) | O17: =IF(L17="",0,(4-L17)*H17)
A18: LO-14 | B18: Security Value Realization | C18: Are licensed identity protections (multifactor authentication, conditional access) deployed to all users, including clinical and remote access? | D18: All users, including clinicians, vendors and remote users, are covered by MFA and conditional access policies that are already licensed. | E18: Identity provider reports of MFA and policy coverage. | F18: CPG-E: Multifactor Authentication | G18: HIPAA 45 CFR 164.312(d); NIST CSF 2.0 PR.AA | H18: 3 | K18: Deploy the MFA and conditional access capabilities you already license to 100% of users. | L18: =IF(OR(I18="",I18="N/A"),"",VALUE(LEFT(I18,1))) | M18: =IF(L18="",0,L18*H18) | N18: =IF(L18="",0,H18) | O18: =IF(L18="",0,(4-L18)*H18)
A19: LO-15 | B19: Security Value Realization | C19: Are licensed endpoint protection and device management deployed to all endpoints, including shared clinical workstations? | D19: Every supported endpoint is managed and protected by the licensed tools, with exceptions documented and compensating controls applied. | E19: Endpoint management and protection coverage reports. | F19: CPG-E: Mitigate Known Vulnerabilities; CPG-X: Configuration Management | G19: NIST CSF 2.0 PR.PS | H19: 3 | K19: Close coverage gaps for licensed endpoint management and protection, prioritizing clinical areas. | L19: =IF(OR(I19="",I19="N/A"),"",VALUE(LEFT(I19,1))) | M19: =IF(L19="",0,L19*H19) | N19: =IF(L19="",0,H19) | O19: =IF(L19="",0,(4-L19)*H19)
A20: LO-16 | B20: Security Value Realization | C20: Are licensed email protection and data protection features (encryption, data loss prevention, labeling) enabled for PHI? | D20: Licensed email filtering, message encryption and data loss prevention policies protect PHI in email and collaboration tools. | E20: Email security and data protection policy configuration. | F20: CPG-E: Email Security; CPG-E: Strong Encryption | G20: HIPAA 45 CFR 164.312(e)(1); NIST CSF 2.0 PR.DS | H20: 2 | K20: Enable licensed email protection, message encryption and DLP policies for PHI. | L20: =IF(OR(I20="",I20="N/A"),"",VALUE(LEFT(I20,1))) | M20: =IF(L20="",0,L20*H20) | N20: =IF(L20="",0,H20) | O20: =IF(L20="",0,(4-L20)*H20)
A21: LO-17 | B21: Cloud Cost | C21: Are cloud subscriptions tagged and costs allocated to departments or applications? | D21: All cloud resources carry ownership and cost-center tags, and monthly cost is allocated and reviewed by owners. | E21: Tagging policy; cost allocation report. | G21: FinOps Framework (Inform) | H21: 2 | K21: Enforce a tagging policy and allocate cloud cost to owners monthly. | L21: =IF(OR(I21="",I21="N/A"),"",VALUE(LEFT(I21,1))) | M21: =IF(L21="",0,L21*H21) | N21: =IF(L21="",0,H21) | O21: =IF(L21="",0,(4-L21)*H21)
A22: LO-18 | B22: Cloud Cost | C22: Are reservations, savings plans and hybrid-use benefits applied where eligible? | D22: Eligible workloads use commitment discounts and existing license benefits, reviewed quarterly. | E22: Commitment coverage report. | G22: FinOps Framework (Optimize) | H22: 2 | K22: Review eligible workloads quarterly for commitment discounts and existing-license benefits. | L22: =IF(OR(I22="",I22="N/A"),"",VALUE(LEFT(I22,1))) | M22: =IF(L22="",0,L22*H22) | N22: =IF(L22="",0,H22) | O22: =IF(L22="",0,(4-L22)*H22)
A23: LO-19 | B23: Cloud Cost | C23: Are idle or oversized cloud resources identified and rightsized at least monthly? | D23: Idle and oversized resources are detected automatically and rightsized or removed every month. | E23: Rightsizing recommendations and actions taken. | G23: FinOps Framework (Optimize) | H23: 2 | K23: Act on rightsizing and idle-resource recommendations every month. | L23: =IF(OR(I23="",I23="N/A"),"",VALUE(LEFT(I23,1))) | M23: =IF(L23="",0,L23*H23) | N23: =IF(L23="",0,H23) | O23: =IF(L23="",0,(4-L23)*H23)
A24: LO-20 | B24: Cloud Cost | C24: Are budgets and spending alerts configured for cloud subscriptions? | D24: Every subscription has a budget and alerts routed to its owner; anomalies are investigated. | E24: Budget and alert configuration. | G24: FinOps Framework (Operate) | H24: 1 | K24: Configure budgets and alerts for every subscription. | L24: =IF(OR(I24="",I24="N/A"),"",VALUE(LEFT(I24,1))) | M24: =IF(L24="",0,L24*H24) | N24: =IF(L24="",0,H24) | O24: =IF(L24="",0,(4-L24)*H24)
A25: LO-21 | B25: Programs & Negotiation | C25: Has eligibility for nonprofit, healthcare or rural hospital licensing programs and discounts been verified? | D25: Eligibility for applicable programs (e.g., nonprofit pricing and the 2024 Microsoft program for rural hospitals) has been verified and applied. | E25: Eligibility confirmation; program enrollment. | G25: AHA, June 10, 2024 (Microsoft rural hospital program) | H25: 2 | K25: Verify eligibility for nonprofit and rural hospital programs and enroll where eligible. | L25: =IF(OR(I25="",I25="N/A"),"",VALUE(LEFT(I25,1))) | M25: =IF(L25="",0,L25*H25) | N25: =IF(L25="",0,H25) | O25: =IF(L25="",0,(4-L25)*H25)
A26: LO-22 | B26: Programs & Negotiation | C26: Is the agreement type (e.g., Enterprise Agreement, CSP, MCA) reviewed against current size and needs before renewal? | D26: Before each renewal, the agreement type and product mix are compared with alternatives and current needs. | E26: Renewal analysis. | G26: FinOps Framework (Optimize) | H26: 2 | K26: Compare agreement types and product mix before each renewal. | L26: =IF(OR(I26="",I26="N/A"),"",VALUE(LEFT(I26,1))) | M26: =IF(L26="",0,L26*H26) | N26: =IF(L26="",0,H26) | O26: =IF(L26="",0,(4-L26)*H26)
A27: LO-23 | B27: Programs & Negotiation | C27: Are savings from license optimization reinvested in documented security or modernization priorities? | D27: Savings are tracked and reinvested through documented decisions in security and modernization priorities. | E27: Budget decisions referencing savings. | G27: NIST CSF 2.0 GV.RM | H27: 1 | K27: Track savings and earmark them for the highest-priority security and modernization gaps. | L27: =IF(OR(I27="",I27="N/A"),"",VALUE(LEFT(I27,1))) | M27: =IF(L27="",0,L27*H27) | N27: =IF(L27="",0,H27) | O27: =IF(L27="",0,(4-L27)*H27)
A28: LO-24 | B28: Programs & Negotiation | C28: Is license compliance risk assessed with a defensible effective license position? | D28: An effective license position is maintained for major vendors and audit exposure is known and managed. | E28: Effective license position report. | G28: ISO/IEC 19770-1 | H28: 2 | K28: Produce an effective license position for major vendors and address shortfalls. | L28: =IF(OR(I28="",I28="N/A"),"",VALUE(LEFT(I28,1))) | M28: =IF(L28="",0,L28*H28) | N28: =IF(L28="",0,H28) | O28: =IF(L28="",0,(4-L28)*H28)

Sheet App Modernization
A1: App Modernization — Maturity Questionnaire
A2: Answer each question in the yellow column using the 0–4 scale (see Start Here). Grey columns are calculated.
A4: ID | B4: Dimension | C4: Question | D4: What “4 - Optimized” looks like | E4: Evidence to review | F4: HHS CPG mapping | G4: Other references | H4: Weight | I4: Answer | J4: Notes | K4: Recommended action if gap | L4: Score | M4: Weighted score | N4: Weight applied | O4: Gap points
A5: AM-01 | B5: Portfolio Visibility | C5: Is there a complete inventory of applications with business owner, technical owner, vendor and hosting model? | D5: Every application is inventoried with owners, vendor, hosting model, users and data handled, and the inventory is kept current. | E5: Application inventory (see sheet App Portfolio Triage). | F5: CPG-X: Asset Inventory | G5: NIST CSF 2.0 ID.AM | H5: 3 | K5: Complete the App Portfolio Triage sheet for every application. | L5: =IF(OR(I5="",I5="N/A"),"",VALUE(LEFT(I5,1))) | M5: =IF(L5="",0,L5*H5) | N5: =IF(L5="",0,H5) | O5: =IF(L5="",0,(4-L5)*H5)
A6: AM-02 | B6: Portfolio Visibility | C6: Are dependencies between applications (interfaces, databases, HL7 or FHIR feeds, shared infrastructure) documented? | D6: Dependencies are mapped and maintained so that the impact of any change or outage can be traced. | E6: Interface catalog; dependency map. | G6: NIST CSF 2.0 ID.AM | H6: 3 | K6: Map interfaces and dependencies for critical applications first. | L6: =IF(OR(I6="",I6="N/A"),"",VALUE(LEFT(I6,1))) | M6: =IF(L6="",0,L6*H6) | N6: =IF(L6="",0,H6) | O6: =IF(L6="",0,(4-L6)*H6)
A7: AM-03 | B7: Portfolio Visibility | C7: Is each application classified by its criticality to patient care, revenue cycle and operations? | D7: Each application has a criticality rating approved by clinical and business owners and used to prioritize investment and recovery. | E7: Criticality ratings; applications and data criticality analysis. | G7: HIPAA 45 CFR 164.308(a)(7)(ii)(E); NIST CSF 2.0 ID.AM | H7: 3 | K7: Rate each application’s criticality with clinical and business owners. | L7: =IF(OR(I7="",I7="N/A"),"",VALUE(LEFT(I7,1))) | M7: =IF(L7="",0,L7*H7) | N7: =IF(L7="",0,H7) | O7: =IF(L7="",0,(4-L7)*H7)
A8: AM-04 | B8: Portfolio Visibility | C8: Is the application inventory reviewed at least annually and updated with every change? | D8: Inventory updates are part of change management and a full review takes place at least annually. | E8: Change records referencing the inventory; last review date. | G8: NIST CSF 2.0 ID.AM | H8: 2 | K8: Make inventory updates a required step of change management. | L8: =IF(OR(I8="",I8="N/A"),"",VALUE(LEFT(I8,1))) | M8: =IF(L8="",0,L8*H8) | N8: =IF(L8="",0,H8) | O8: =IF(L8="",0,(4-L8)*H8)
A9: AM-05 | B9: Lifecycle & Supportability | C9: Do you know which applications depend on platforms past end of support (e.g., Windows 10, older Windows Server or SQL Server)? | D9: Every application’s dependence on unsupported operating systems, databases or frameworks is known and reported. | E9: Platform support status report. | F9: CPG-E: Mitigate Known Vulnerabilities | G9: NIST CSF 2.0 ID.RA | H9: 3 | K9: Identify all applications that depend on unsupported platforms. | L9: =IF(OR(I9="",I9="N/A"),"",VALUE(LEFT(I9,1))) | M9: =IF(L9="",0,L9*H9) | N9: =IF(L9="",0,H9) | O9: =IF(L9="",0,(4-L9)*H9)
A10: AM-06 | B10: Lifecycle & Supportability | C10: Is there a funded plan for each unsupported platform (upgrade, isolate, retire or purchase extended updates)? | D10: Each unsupported platform has an approved, funded plan with an owner and a target date. | E10: Remediation plan and budget. | F10: CPG-X: Cybersecurity Mitigation | G10: NIST CSF 2.0 GV.RM, ID.RA | H10: 3 | K10: Approve and fund a plan with an owner and date for every unsupported platform. | L10: =IF(OR(I10="",I10="N/A"),"",VALUE(LEFT(I10,1))) | M10: =IF(L10="",0,L10*H10) | N10: =IF(L10="",0,H10) | O10: =IF(L10="",0,(4-L10)*H10)
A11: AM-07 | B11: Lifecycle & Supportability | C11: Are vendor support status, roadmap and contract terms tracked for clinical applications? | D11: Vendor support dates, roadmap commitments and contract terms are tracked and reviewed before renewals. | E11: Vendor register. | G11: NIST CSF 2.0 GV.SC | H11: 2 | K11: Track support status and roadmap commitments for every clinical application vendor. | L11: =IF(OR(I11="",I11="N/A"),"",VALUE(LEFT(I11,1))) | M11: =IF(L11="",0,L11*H11) | N11: =IF(L11="",0,H11) | O11: =IF(L11="",0,(4-L11)*H11)
A12: AM-08 | B12: Lifecycle & Supportability | C12: Are legacy systems that cannot be upgraded (including medical device software) isolated with compensating controls? | D12: Systems that cannot be upgraded are isolated in dedicated segments with restricted access and enhanced monitoring. | E12: Network segmentation design; exception register. | F12: CPG-X: Network Segmentation | G12: NIST CSF 2.0 PR.IR | H12: 3 | K12: Isolate non-upgradable systems and document compensating controls. | L12: =IF(OR(I12="",I12="N/A"),"",VALUE(LEFT(I12,1))) | M12: =IF(L12="",0,L12*H12) | N12: =IF(L12="",0,H12) | O12: =IF(L12="",0,(4-L12)*H12)
A13: AM-09 | B13: Rationalization & Roadmap | C13: Does each application have a documented disposition (retire, retain, rehost, replatform, refactor or replace)? | D13: Every application has an approved disposition based on business value and technical risk. | E13: Dispositions in the application inventory. | G13: Microsoft Cloud Adoption Framework (Plan) | H13: 2 | K13: Assign a disposition to each application using the App Portfolio Triage sheet. | L13: =IF(OR(I13="",I13="N/A"),"",VALUE(LEFT(I13,1))) | M13: =IF(L13="",0,L13*H13) | N13: =IF(L13="",0,H13) | O13: =IF(L13="",0,(4-L13)*H13)
A14: AM-10 | B14: Rationalization & Roadmap | C14: Is there a sequenced modernization roadmap aligned with business priorities and regulatory deadlines? | D14: A funded roadmap sequences modernization by risk and value and reflects regulatory deadlines such as HIPAA Security Rule updates. | E14: Modernization roadmap. | G14: Microsoft Cloud Adoption Framework (Plan) | H14: 2 | K14: Build a sequenced roadmap from the dispositions, highest risk and value first. | L14: =IF(OR(I14="",I14="N/A"),"",VALUE(LEFT(I14,1))) | M14: =IF(L14="",0,L14*H14) | N14: =IF(L14="",0,H14) | O14: =IF(L14="",0,(4-L14)*H14)
A15: AM-11 | B15: Rationalization & Roadmap | C15: Are redundant applications with overlapping functions identified for consolidation? | D15: Overlapping applications are identified and consolidation decisions are made and tracked. | E15: Capability-to-application map. | G15: Application portfolio management practice | H15: 1 | K15: Map business capabilities to applications to expose overlaps. | L15: =IF(OR(I15="",I15="N/A"),"",VALUE(LEFT(I15,1))) | M15: =IF(L15="",0,L15*H15) | N15: =IF(L15="",0,H15) | O15: =IF(L15="",0,(4-L15)*H15)
A16: AM-12 | B16: Rationalization & Roadmap | C16: Is the total cost of ownership known for major applications? | D16: Licensing, infrastructure, support and staff costs are known for each major application. | E16: Cost per application. | G16: FinOps Framework (Inform) | H16: 1 | K16: Estimate total cost of ownership for the top applications by spend. | L16: =IF(OR(I16="",I16="N/A"),"",VALUE(LEFT(I16,1))) | M16: =IF(L16="",0,L16*H16) | N16: =IF(L16="",0,H16) | O16: =IF(L16="",0,(4-L16)*H16)
A17: AM-13 | B17: Engineering & Release | C17: Are changes deployed through a controlled, repeatable release process with approval and rollback? | D17: All production changes follow an approved, repeatable release process with tested rollback, and configurations are baselined. | E17: Change management records; release procedure. | F17: CPG-X: Configuration Management | G17: NIST CSF 2.0 PR.PS | H17: 3 | K17: Standardize the release process with approval gates and tested rollback. | L17: =IF(OR(I17="",I17="N/A"),"",VALUE(LEFT(I17,1))) | M17: =IF(L17="",0,L17*H17) | N17: =IF(L17="",0,H17) | O17: =IF(L17="",0,(4-L17)*H17)
A18: AM-14 | B18: Engineering & Release | C18: Is automated testing used for critical applications before release? | D18: Critical applications have automated tests that run before every release, including regression of key clinical workflows. | E18: Test reports from recent releases. | G18: NIST SP 800-218 (SSDF) PW.8 | H18: 2 | K18: Automate regression tests for the critical workflows of the most important applications. | L18: =IF(OR(I18="",I18="N/A"),"",VALUE(LEFT(I18,1))) | M18: =IF(L18="",0,L18*H18) | N18: =IF(L18="",0,H18) | O18: =IF(L18="",0,(4-L18)*H18)
A19: AM-15 | B19: Engineering & Release | C19: Are secure development practices (code review, dependency scanning, secrets management) applied to in-house and customized code? | D19: Code review, dependency and vulnerability scanning and secrets management are applied to all in-house and customized code. | E19: Pipeline configuration; scan results. | G19: NIST SP 800-218 (SSDF) PW, RV | H19: 2 | K19: Add code review, dependency scanning and secrets management to every pipeline. | L19: =IF(OR(I19="",I19="N/A"),"",VALUE(LEFT(I19,1))) | M19: =IF(L19="",0,L19*H19) | N19: =IF(L19="",0,H19) | O19: =IF(L19="",0,(4-L19)*H19)
A20: AM-16 | B20: Engineering & Release | C20: If AI-assisted engineering is used, is it governed by policy (approved tools, data restrictions, human review)? | D20: A policy defines approved AI tools, prohibits PHI in unapproved tools, and requires human review of AI-generated changes. | E20: AI usage policy; review records. | G20: NIST CSF 2.0 GV.PO | H20: 2 | K20: Publish an AI-assisted engineering policy with approved tools, data rules and mandatory human review. | L20: =IF(OR(I20="",I20="N/A"),"",VALUE(LEFT(I20,1))) | M20: =IF(L20="",0,L20*H20) | N20: =IF(L20="",0,H20) | O20: =IF(L20="",0,(4-L20)*H20)
A21: AM-17 | B21: Resilience & Recovery | C21: Are backups of critical applications and data protected from tampering and is restoration tested? | D21: Backups are immutable or offline, and restoration of critical applications is tested at least annually. | E21: Backup configuration; restoration test results. | G21: HIPAA 45 CFR 164.308(a)(7)(ii)(A),(D); NIST CSF 2.0 PR.DS, RC.RP | H21: 3 | K21: Make backups immutable or offline and test restoration of critical applications. | L21: =IF(OR(I21="",I21="N/A"),"",VALUE(LEFT(I21,1))) | M21: =IF(L21="",0,L21*H21) | N21: =IF(L21="",0,H21) | O21: =IF(L21="",0,(4-L21)*H21)
A22: AM-18 | B22: Resilience & Recovery | C22: Do critical applications have recovery time and recovery point objectives that are tested? | D22: Approved recovery objectives exist for each critical application and are validated by recovery exercises. | E22: Recovery objectives; disaster recovery test reports. | G22: HIPAA 45 CFR 164.308(a)(7)(ii)(B); NIST CSF 2.0 RC.RP | H22: 3 | K22: Define and test recovery objectives for each critical application. | L22: =IF(OR(I22="",I22="N/A"),"",VALUE(LEFT(I22,1))) | M22: =IF(L22="",0,L22*H22) | N22: =IF(L22="",0,H22) | O22: =IF(L22="",0,(4-L22)*H22)
A23: AM-19 | B23: Resilience & Recovery | C23: Are downtime procedures for clinical workflows documented and exercised? | D23: Clinical departments have current downtime procedures and exercise them at least annually. | E23: Downtime procedures; exercise records. | G23: HIPAA 45 CFR 164.308(a)(7)(ii)(C) | H23: 3 | K23: Document and exercise downtime procedures with clinical departments. | L23: =IF(OR(I23="",I23="N/A"),"",VALUE(LEFT(I23,1))) | M23: =IF(L23="",0,L23*H23) | N23: =IF(L23="",0,H23) | O23: =IF(L23="",0,(4-L23)*H23)
A24: AM-20 | B24: Resilience & Recovery | C24: Is monitoring in place to detect application outages and performance degradation? | D24: Critical applications are monitored end to end with alerts routed to accountable teams. | E24: Monitoring dashboards; alert routing. | G24: NIST CSF 2.0 DE.CM | H24: 2 | K24: Implement end-to-end monitoring and alerting for critical applications. | L24: =IF(OR(I24="",I24="N/A"),"",VALUE(LEFT(I24,1))) | M24: =IF(L24="",0,L24*H24) | N24: =IF(L24="",0,H24) | O24: =IF(L24="",0,(4-L24)*H24)
A25: AM-21 | B25: Cloud & Data Readiness | C25: Is there a cloud foundation (identity, network, security, cost governance) in place before migrations? | D25: A governed cloud foundation exists and every migration lands on it. | E25: Cloud foundation design and policies. | G25: Microsoft Cloud Adoption Framework (Ready) | H25: 2 | K25: Establish a governed cloud foundation before migrating workloads. | L25: =IF(OR(I25="",I25="N/A"),"",VALUE(LEFT(I25,1))) | M25: =IF(L25="",0,L25*H25) | N25: =IF(L25="",0,H25) | O25: =IF(L25="",0,(4-L25)*H25)
A26: AM-22 | B26: Cloud & Data Readiness | C26: Are business associate agreements in place with all cloud and SaaS providers that handle PHI? | D26: Every provider that creates, receives, maintains or transmits PHI has a business associate agreement and meets your security requirements. | E26: Business associate agreements; vendor security reviews. | F26: CPG-E: Vendor/Supplier Cybersecurity Requirements | G26: HIPAA 45 CFR 164.308(b); NIST CSF 2.0 GV.SC | H26: 3 | K26: Confirm business associate agreements and security requirements for every PHI-handling provider. | L26: =IF(OR(I26="",I26="N/A"),"",VALUE(LEFT(I26,1))) | M26: =IF(L26="",0,L26*H26) | N26: =IF(L26="",0,H26) | O26: =IF(L26="",0,(4-L26)*H26)
A27: AM-23 | B27: Cloud & Data Readiness | C27: Are interfaces moving toward standards-based APIs (e.g., HL7 FHIR) where applicable? | D27: New and modernized interfaces use standards-based APIs and are inventoried and secured. | E27: Interface catalog. | G27: HL7 FHIR | H27: 1 | K27: Prefer standards-based APIs for new and modernized interfaces. | L27: =IF(OR(I27="",I27="N/A"),"",VALUE(LEFT(I27,1))) | M27: =IF(L27="",0,L27*H27) | N27: =IF(L27="",0,H27) | O27: =IF(L27="",0,(4-L27)*H27)
A28: AM-24 | B28: Cloud & Data Readiness | C28: Are data classification, retention and migration rules for PHI defined before applications are moved? | D28: PHI is classified and retention and migration rules are approved before any application is moved. | E28: Data classification and retention policy. | G28: NIST CSF 2.0 PR.DS | H28: 2 | K28: Define PHI classification, retention and migration rules before moving applications. | L28: =IF(OR(I28="",I28="N/A"),"",VALUE(LEFT(I28,1))) | M28: =IF(L28="",0,L28*H28) | N28: =IF(L28="",0,H28) | O28: =IF(L28="",0,(4-L28)*H28)

Sheet Zero Trust
A1: Zero Trust — Maturity Questionnaire
A2: Answer each question in the yellow column using the 0–4 scale (see Start Here). Grey columns are calculated.
A4: ID | B4: Dimension | C4: Question | D4: What “4 - Optimized” looks like | E4: Evidence to review | F4: HHS CPG mapping | G4: Other references | H4: Weight | I4: Answer | J4: Notes | K4: Recommended action if gap | L4: Score | M4: Weighted score | N4: Weight applied | O4: Gap points
A5: ZT-01 | B5: Identity | C5: Is multifactor authentication enforced for remote access, email and privileged accounts? | D5: Phishing-resistant MFA is enforced for all remote access, email and privileged accounts, with no standing exceptions. | E5: Identity provider MFA coverage report. | F5: CPG-E: Multifactor Authentication | G5: HIPAA 45 CFR 164.312(d); CISA ZTMM v2.0 Identity; NIST CSF 2.0 PR.AA | H5: 3 | K5: Enforce MFA for remote access, email and privileged accounts; move privileged users to phishing-resistant methods. | L5: =IF(OR(I5="",I5="N/A"),"",VALUE(LEFT(I5,1))) | M5: =IF(L5="",0,L5*H5) | N5: =IF(L5="",0,H5) | O5: =IF(L5="",0,(4-L5)*H5)
A6: ZT-02 | B6: Identity | C6: Does every workforce member use unique credentials, including on shared clinical workstations? | D6: No shared or generic accounts are used; shared workstations use fast user switching or badge-based sign-in. | E6: Directory report of shared or generic accounts. | F6: CPG-E: Unique Credentials | G6: HIPAA 45 CFR 164.312(a)(2)(i); NIST CSF 2.0 PR.AA | H6: 3 | K6: Eliminate shared accounts; use fast user switching on shared clinical workstations. | L6: =IF(OR(I6="",I6="N/A"),"",VALUE(LEFT(I6,1))) | M6: =IF(L6="",0,L6*H6) | N6: =IF(L6="",0,H6) | O6: =IF(L6="",0,(4-L6)*H6)
A7: ZT-03 | B7: Identity | C7: Are administrator accounts separate from daily user accounts and granted only when needed? | D7: Privileged access uses separate accounts with just-in-time elevation, approval and logging. | E7: Privileged account inventory. | F7: CPG-E: Separate User and Privileged Accounts | G7: CISA ZTMM v2.0 Identity; NIST CSF 2.0 PR.AA | H7: 3 | K7: Separate privileged accounts and adopt just-in-time elevation. | L7: =IF(OR(I7="",I7="N/A"),"",VALUE(LEFT(I7,1))) | M7: =IF(L7="",0,L7*H7) | N7: =IF(L7="",0,H7) | O7: =IF(L7="",0,(4-L7)*H7)
A8: ZT-04 | B8: Identity | C8: Are the accounts of departing workforce members and vendors revoked promptly? | D8: Access is revoked within 24 hours of departure or contract end, verified by periodic reconciliation. | E8: Offboarding records; access reviews. | F8: CPG-E: Revoke Credentials for Departing Workforce Members | G8: HIPAA 45 CFR 164.308(a)(3)(ii)(C) | H8: 3 | K8: Automate revocation from HR and vendor records and reconcile monthly. | L8: =IF(OR(I8="",I8="N/A"),"",VALUE(LEFT(I8,1))) | M8: =IF(L8="",0,L8*H8) | N8: =IF(L8="",0,H8) | O8: =IF(L8="",0,(4-L8)*H8)
A9: ZT-05 | B9: Devices | C9: Is there a complete inventory of endpoints, servers and connected medical devices? | D9: All endpoints, servers, network and medical devices are inventoried automatically with owner and location. | E9: Asset inventory with coverage metrics. | F9: CPG-X: Asset Inventory | G9: CISA ZTMM v2.0 Devices; NIST CSF 2.0 ID.AM | H9: 3 | K9: Implement automated asset discovery, including medical devices. | L9: =IF(OR(I9="",I9="N/A"),"",VALUE(LEFT(I9,1))) | M9: =IF(L9="",0,L9*H9) | N9: =IF(L9="",0,H9) | O9: =IF(L9="",0,(4-L9)*H9)
A10: ZT-06 | B10: Devices | C10: Are known exploited vulnerabilities remediated within defined, risk-based timeframes? | D10: Known exploited and critical vulnerabilities are remediated within defined timeframes, with exceptions approved and tracked. | E10: Vulnerability management reports; exception register. | F10: CPG-E: Mitigate Known Vulnerabilities | G10: NIST CSF 2.0 ID.RA | H10: 3 | K10: Define remediation timeframes by severity and prioritize known exploited vulnerabilities. | L10: =IF(OR(I10="",I10="N/A"),"",VALUE(LEFT(I10,1))) | M10: =IF(L10="",0,L10*H10) | N10: =IF(L10="",0,H10) | O10: =IF(L10="",0,(4-L10)*H10)
A11: ZT-07 | B11: Devices | C11: Is device health and compliance checked before access to PHI is granted? | D11: Access to PHI requires a managed, compliant device; non-compliant devices are restricted automatically. | E11: Conditional access and device compliance policies. | G11: CISA ZTMM v2.0 Devices | H11: 2 | K11: Require compliant, managed devices for access to PHI. | L11: =IF(OR(I11="",I11="N/A"),"",VALUE(LEFT(I11,1))) | M11: =IF(L11="",0,L11*H11) | N11: =IF(L11="",0,H11) | O11: =IF(L11="",0,(4-L11)*H11)
A12: ZT-08 | B12: Devices | C12: Are secure configuration baselines applied and configuration drift monitored? | D12: Approved baselines are applied to all device types and drift is detected and corrected automatically. | E12: Baseline documents; compliance reports. | F12: CPG-X: Configuration Management | G12: NIST CSF 2.0 PR.PS | H12: 2 | K12: Apply security baselines and monitor drift. | L12: =IF(OR(I12="",I12="N/A"),"",VALUE(LEFT(I12,1))) | M12: =IF(L12="",0,L12*H12) | N12: =IF(L12="",0,H12) | O12: =IF(L12="",0,(4-L12)*H12)
A13: ZT-09 | B13: Networks | C13: Is the network segmented so that medical devices, clinical systems, guest and corporate traffic are separated? | D13: Segments separate medical devices, clinical systems, corporate users and guests, with traffic allowed only by explicit policy. | E13: Network segmentation design; firewall rules. | F13: CPG-X: Network Segmentation | G13: CISA ZTMM v2.0 Networks; NIST CSF 2.0 PR.IR | H13: 3 | K13: Segment the network, starting with medical devices and legacy systems. | L13: =IF(OR(I13="",I13="N/A"),"",VALUE(LEFT(I13,1))) | M13: =IF(L13="",0,L13*H13) | N13: =IF(L13="",0,H13) | O13: =IF(L13="",0,(4-L13)*H13)
A14: ZT-10 | B14: Networks | C14: Is remote and vendor access brokered through controlled, logged and time-limited connections? | D14: Vendor and remote access uses brokered, MFA-protected, time-limited sessions that are logged and reviewed. | E14: Remote access architecture; session logs. | F14: CPG-E: Vendor/Supplier Cybersecurity Requirements | G14: CISA ZTMM v2.0 Networks | H14: 3 | K14: Replace standing vendor VPNs with brokered, time-limited access. | L14: =IF(OR(I14="",I14="N/A"),"",VALUE(LEFT(I14,1))) | M14: =IF(L14="",0,L14*H14) | N14: =IF(L14="",0,H14) | O14: =IF(L14="",0,(4-L14)*H14)
A15: ZT-11 | B15: Networks | C15: Is PHI encrypted in transit on internal and external connections? | D15: All connections carrying PHI use current encryption protocols, including internal interfaces. | E15: Interface and protocol inventory. | F15: CPG-E: Strong Encryption | G15: HIPAA 45 CFR 164.312(e)(2)(ii); NIST CSF 2.0 PR.DS | H15: 2 | K15: Encrypt all PHI in transit, including internal HL7 and database connections. | L15: =IF(OR(I15="",I15="N/A"),"",VALUE(LEFT(I15,1))) | M15: =IF(L15="",0,L15*H15) | N15: =IF(L15="",0,H15) | O15: =IF(L15="",0,(4-L15)*H15)
A16: ZT-12 | B16: Applications & Workloads | C16: Are email protections (SPF, DKIM, DMARC, attachment and link scanning) enforced? | D16: SPF, DKIM and DMARC at enforcement, and attachment and link scanning are applied to all mailboxes. | E16: DNS records; email security configuration. | F16: CPG-E: Email Security | G16: NIST CSF 2.0 PR.PS | H16: 3 | K16: Move DMARC to enforcement and enable attachment and link scanning. | L16: =IF(OR(I16="",I16="N/A"),"",VALUE(LEFT(I16,1))) | M16: =IF(L16="",0,L16*H16) | N16: =IF(L16="",0,H16) | O16: =IF(L16="",0,(4-L16)*H16)
A17: ZT-13 | B17: Applications & Workloads | C17: Is access to applications granted per application based on identity and context, rather than network location? | D17: Applications are accessed through identity-aware policies; being on the internal network does not grant access by itself. | E17: Application access policies. | G17: CISA ZTMM v2.0 Applications and Workloads | H17: 2 | K17: Publish critical applications through identity-aware access policies. | L17: =IF(OR(I17="",I17="N/A"),"",VALUE(LEFT(I17,1))) | M17: =IF(L17="",0,L17*H17) | N17: =IF(L17="",0,H17) | O17: =IF(L17="",0,(4-L17)*H17)
A18: ZT-14 | B18: Applications & Workloads | C18: Are internet-facing systems and critical applications tested for vulnerabilities at least annually? | D18: Penetration tests and vulnerability scans cover internet-facing and critical systems at least annually, with findings tracked. | E18: Penetration test reports. | F18: CPG-X: Cybersecurity Testing | G18: NIST CSF 2.0 ID.RA | H18: 2 | K18: Test internet-facing and critical systems annually and track findings to closure. | L18: =IF(OR(I18="",I18="N/A"),"",VALUE(LEFT(I18,1))) | M18: =IF(L18="",0,L18*H18) | N18: =IF(L18="",0,H18) | O18: =IF(L18="",0,(4-L18)*H18)
A19: ZT-15 | B19: Applications & Workloads | C19: Are vendors required to disclose vulnerabilities and report incidents that affect your systems or data? | D19: Contracts require vendors to disclose vulnerabilities and report incidents within defined timeframes, and compliance is monitored. | E19: Contract clauses; vendor notifications received. | F19: CPG-X: Third Party Vulnerability Disclosure; CPG-X: Third Party Incident Reporting | G19: HIPAA 45 CFR 164.308(b); NIST CSF 2.0 GV.SC | H19: 3 | K19: Add vulnerability disclosure and incident reporting clauses to vendor contracts. | L19: =IF(OR(I19="",I19="N/A"),"",VALUE(LEFT(I19,1))) | M19: =IF(L19="",0,L19*H19) | N19: =IF(L19="",0,H19) | O19: =IF(L19="",0,(4-L19)*H19)
A20: ZT-16 | B20: Data | C20: Is PHI encrypted at rest on servers, endpoints, removable media and backups? | D20: Encryption at rest protects PHI on all servers, endpoints, removable media and backups, with keys managed centrally. | E20: Encryption status reports. | F20: CPG-E: Strong Encryption | G20: HIPAA 45 CFR 164.312(a)(2)(iv); NIST CSF 2.0 PR.DS | H20: 3 | K20: Enable encryption at rest everywhere PHI is stored and manage keys centrally. | L20: =IF(OR(I20="",I20="N/A"),"",VALUE(LEFT(I20,1))) | M20: =IF(L20="",0,L20*H20) | N20: =IF(L20="",0,H20) | O20: =IF(L20="",0,(4-L20)*H20)
A21: ZT-17 | B21: Data | C21: Is PHI classified and are its storage locations known? | D21: PHI is classified and its locations across applications, file shares and cloud services are known and monitored. | E21: Data map; classification reports. | G21: CISA ZTMM v2.0 Data; NIST CSF 2.0 ID.AM | H21: 2 | K21: Map where PHI is stored and apply classification labels. | L21: =IF(OR(I21="",I21="N/A"),"",VALUE(LEFT(I21,1))) | M21: =IF(L21="",0,L21*H21) | N21: =IF(L21="",0,H21) | O21: =IF(L21="",0,(4-L21)*H21)
A22: ZT-18 | B22: Data | C22: Are data loss prevention controls applied to email, cloud storage and endpoints? | D22: DLP policies detect and block unauthorized transfer of PHI across email, cloud storage and endpoints. | E22: DLP policies and incident reports. | G22: CISA ZTMM v2.0 Data; NIST CSF 2.0 PR.DS | H22: 2 | K22: Deploy DLP policies for PHI across email, cloud storage and endpoints. | L22: =IF(OR(I22="",I22="N/A"),"",VALUE(LEFT(I22,1))) | M22: =IF(L22="",0,L22*H22) | N22: =IF(L22="",0,H22) | O22: =IF(L22="",0,(4-L22)*H22)
A23: ZT-19 | B23: Data | C23: Are backups isolated from the production environment and protected against ransomware? | D23: Backups are logically or physically isolated, immutable and protected by separate credentials. | E23: Backup architecture. | G23: NIST CSF 2.0 PR.DS | H23: 3 | K23: Isolate backups with separate credentials and immutability. | L23: =IF(OR(I23="",I23="N/A"),"",VALUE(LEFT(I23,1))) | M23: =IF(L23="",0,L23*H23) | N23: =IF(L23="",0,H23) | O23: =IF(L23="",0,(4-L23)*H23)
A24: ZT-20 | B24: Visibility & Analytics | C24: Are security logs from identity, endpoints, network and key applications collected centrally? | D24: Logs from identity, endpoints, network, cloud and key clinical applications are centralized and retained per policy. | E24: Log source inventory; retention settings. | F24: CPG-X: Centralized Log Collection | G24: HIPAA 45 CFR 164.312(b); CISA ZTMM v2.0 Visibility and Analytics | H24: 3 | K24: Centralize security logs from identity, endpoints, network and key applications. | L24: =IF(OR(I24="",I24="N/A"),"",VALUE(LEFT(I24,1))) | M24: =IF(L24="",0,L24*H24) | N24: =IF(L24="",0,H24) | O24: =IF(L24="",0,(4-L24)*H24)
A25: ZT-21 | B25: Visibility & Analytics | C25: Is there 24x7 capability, in-house or managed, to detect and respond to relevant threats? | D25: A 24x7 capability detects and responds to the threats most relevant to healthcare, with defined escalation. | E25: Service contract or SOC procedures; detection metrics. | F25: CPG-X: Detect and Respond to Relevant Threats and TTPs | G25: NIST CSF 2.0 DE.CM, DE.AE, RS.MA | H25: 3 | K25: Establish 24x7 detection and response, in-house or through a managed service. | L25: =IF(OR(I25="",I25="N/A"),"",VALUE(LEFT(I25,1))) | M25: =IF(L25="",0,L25*H25) | N25: =IF(L25="",0,H25) | O25: =IF(L25="",0,(4-L25)*H25)
A26: ZT-22 | B26: Visibility & Analytics | C26: Are records of access to PHI reviewed regularly? | D26: Access to PHI is reviewed regularly, with automated alerts for unusual activity. | E26: Information system activity review records. | G26: HIPAA 45 CFR 164.308(a)(1)(ii)(D) | H26: 2 | K26: Schedule regular reviews of PHI access and alert on unusual activity. | L26: =IF(OR(I26="",I26="N/A"),"",VALUE(LEFT(I26,1))) | M26: =IF(L26="",0,L26*H26) | N26: =IF(L26="",0,H26) | O26: =IF(L26="",0,(4-L26)*H26)
A27: ZT-23 | B27: Governance & Readiness | C27: Has a security risk analysis been completed in the last 12 months, driving a risk management plan? | D27: A risk analysis covering all systems with PHI is updated at least annually and drives a funded risk management plan. | E27: Risk analysis report; risk management plan. | G27: HIPAA 45 CFR 164.308(a)(1)(ii)(A),(B); NIST CSF 2.0 GV.RM | H27: 3 | K27: Update the security risk analysis and link it to a funded risk management plan. | L27: =IF(OR(I27="",I27="N/A"),"",VALUE(LEFT(I27,1))) | M27: =IF(L27="",0,L27*H27) | N27: =IF(L27="",0,H27) | O27: =IF(L27="",0,(4-L27)*H27)
A28: ZT-24 | B28: Governance & Readiness | C28: Is there a tested incident response plan covering ransomware and extended downtime? | D28: An incident response plan covering ransomware and extended downtime is tested at least annually with clinical and executive participation. | E28: Incident response plan; exercise reports. | F28: CPG-E: Basic Incident Planning and Preparedness; CPG-X: Centralized Incident Planning and Preparedness | G28: HIPAA 45 CFR 164.308(a)(6); NIST CSF 2.0 RS.MA | H28: 3 | K28: Test the incident response plan annually with a ransomware and downtime scenario. | L28: =IF(OR(I28="",I28="N/A"),"",VALUE(LEFT(I28,1))) | M28: =IF(L28="",0,L28*H28) | N28: =IF(L28="",0,H28) | O28: =IF(L28="",0,(4-L28)*H28)
A29: ZT-25 | B29: Governance & Readiness | C29: Does the whole workforce complete cybersecurity awareness training, including phishing exercises? | D29: All workforce members, including clinicians and contractors, complete training and phishing exercises at least annually. | E29: Training completion and phishing exercise results. | F29: CPG-E: Basic Cybersecurity Training | G29: HIPAA 45 CFR 164.308(a)(5); NIST CSF 2.0 PR.AT | H29: 2 | K29: Run annual training and periodic phishing exercises for the whole workforce. | L29: =IF(OR(I29="",I29="N/A"),"",VALUE(LEFT(I29,1))) | M29: =IF(L29="",0,L29*H29) | N29: =IF(L29="",0,H29) | O29: =IF(L29="",0,(4-L29)*H29)
A30: ZT-26 | B30: Governance & Readiness | C30: Are cybersecurity requirements included in vendor contracts and verified before onboarding? | D30: Vendors are assessed before onboarding and contracts include cybersecurity requirements that are monitored. | E30: Vendor assessments; contract templates. | F30: CPG-E: Vendor/Supplier Cybersecurity Requirements | G30: NIST CSF 2.0 GV.SC | H30: 3 | K30: Assess vendors before onboarding and standardize cybersecurity contract clauses. | L30: =IF(OR(I30="",I30="N/A"),"",VALUE(LEFT(I30,1))) | M30: =IF(L30="",0,L30*H30) | N30: =IF(L30="",0,H30) | O30: =IF(L30="",0,(4-L30)*H30)
A31: ZT-27 | B31: Governance & Readiness | C31: Are identified vulnerabilities and gaps tracked to closure with owners and dates? | D31: Every gap has an owner and date, and progress is reported to leadership. | E31: Remediation tracker. | F31: CPG-X: Cybersecurity Mitigation | G31: NIST CSF 2.0 ID.IM | H31: 2 | K31: Track every gap to closure with an owner and target date. | L31: =IF(OR(I31="",I31="N/A"),"",VALUE(LEFT(I31,1))) | M31: =IF(L31="",0,L31*H31) | N31: =IF(L31="",0,H31) | O31: =IF(L31="",0,(4-L31)*H31)
A32: ZT-28 | B32: Governance & Readiness | C32: Is there a Zero Trust strategy with a target maturity per pillar and an executive sponsor? | D32: An approved strategy sets target maturity for each CISA ZTMM pillar, with an executive sponsor and a funded roadmap. | E32: Zero Trust strategy document. | G32: CISA ZTMM v2.0 (Governance); NIST CSF 2.0 GV.OC | H32: 1 | K32: Define target maturity per pillar and assign an executive sponsor. | L32: =IF(OR(I32="",I32="N/A"),"",VALUE(LEFT(I32,1))) | M32: =IF(L32="",0,L32*H32) | N32: =IF(L32="",0,H32) | O32: =IF(L32="",0,(4-L32)*H32)

Sheet Dashboard
A1: Dashboard
A2: Weighted maturity scores on a 0–4 scale. Unanswered and N/A questions are excluded.
A4: Service | B4: Score (0–4) | C4: Score % | D4: Maturity level | E4: Answered | F4: Questions
A5: License Optimization | B5: =IFERROR(SUMIFS(AllItems!$I$2:$I$77,AllItems!$A$2:$A$77,A5)/SUMIFS(AllItems!$H$2:$H$77,AllItems!$A$2:$A$77,A5),"") | C5: =IF(B5="","",B5/4) | D5: =IF(B5="","Not assessed",INDEX(Lists!$B$2:$B$6,MIN(5,INT(B5)+1))) | E5: =COUNTIFS(AllItems!$A$2:$A$77,A5,AllItems!$G$2:$G$77,">=0") | F5: =COUNTIFS(AllItems!$A$2:$A$77,A5)
A6: App Modernization | B6: =IFERROR(SUMIFS(AllItems!$I$2:$I$77,AllItems!$A$2:$A$77,A6)/SUMIFS(AllItems!$H$2:$H$77,AllItems!$A$2:$A$77,A6),"") | C6: =IF(B6="","",B6/4) | D6: =IF(B6="","Not assessed",INDEX(Lists!$B$2:$B$6,MIN(5,INT(B6)+1))) | E6: =COUNTIFS(AllItems!$A$2:$A$77,A6,AllItems!$G$2:$G$77,">=0") | F6: =COUNTIFS(AllItems!$A$2:$A$77,A6)
A7: Zero Trust | B7: =IFERROR(SUMIFS(AllItems!$I$2:$I$77,AllItems!$A$2:$A$77,A7)/SUMIFS(AllItems!$H$2:$H$77,AllItems!$A$2:$A$77,A7),"") | C7: =IF(B7="","",B7/4) | D7: =IF(B7="","Not assessed",INDEX(Lists!$B$2:$B$6,MIN(5,INT(B7)+1))) | E7: =COUNTIFS(AllItems!$A$2:$A$77,A7,AllItems!$G$2:$G$77,">=0") | F7: =COUNTIFS(AllItems!$A$2:$A$77,A7)
A8: Overall | B8: =IFERROR(SUM(AllItems!$I$2:$I$77)/SUM(AllItems!$H$2:$H$77),"") | C8: =IF(B8="","",B8/4) | D8: =IF(B8="","Not assessed",INDEX(Lists!$B$2:$B$6,MIN(5,INT(B8)+1))) | E8: =SUM(E5:E7) | F8: =SUM(F5:F7)
A10: HHS Cybersecurity Performance Goals
A11: Goal type | B11: Goals | C11: Meets | D11: Partially meets | E11: Gap | F11: Not assessed
A12: Essential | B12: =COUNTIFS('CPG Crosswalk'!$A$5:$A$24,A12) | C12: =COUNTIFS('CPG Crosswalk'!$A$5:$A$24,A12,'CPG Crosswalk'!$E$5:$E$24,"Meets*") | D12: =COUNTIFS('CPG Crosswalk'!$A$5:$A$24,A12,'CPG Crosswalk'!$E$5:$E$24,"Partially*") | E12: =COUNTIFS('CPG Crosswalk'!$A$5:$A$24,A12,'CPG Crosswalk'!$E$5:$E$24,"Gap") | F12: =COUNTIFS('CPG Crosswalk'!$A$5:$A$24,A12,'CPG Crosswalk'!$E$5:$E$24,"Not assessed")
A13: Enhanced | B13: =COUNTIFS('CPG Crosswalk'!$A$5:$A$24,A13) | C13: =COUNTIFS('CPG Crosswalk'!$A$5:$A$24,A13,'CPG Crosswalk'!$E$5:$E$24,"Meets*") | D13: =COUNTIFS('CPG Crosswalk'!$A$5:$A$24,A13,'CPG Crosswalk'!$E$5:$E$24,"Partially*") | E13: =COUNTIFS('CPG Crosswalk'!$A$5:$A$24,A13,'CPG Crosswalk'!$E$5:$E$24,"Gap") | F13: =COUNTIFS('CPG Crosswalk'!$A$5:$A$24,A13,'CPG Crosswalk'!$E$5:$E$24,"Not assessed")
A15: License Optimization — by dimension
A16: Dimension | B16: Score (0–4) | C16: Score % | D16: Maturity level
A17: Governance & Ownership | B17: =IFERROR(SUMIFS(AllItems!$I$2:$I$77,AllItems!$A$2:$A$77,"License Optimization",AllItems!$C$2:$C$77,A17)/SUMIFS(AllItems!$H$2:$H$77,AllItems!$A$2:$A$77,"License Optimization",AllItems!$C$2:$C$77,A17),"") | C17: =IF(B17="","",B17/4) | D17: =IF(B17="","Not assessed",INDEX(Lists!$B$2:$B$6,MIN(5,INT(B17)+1)))
A18: Entitlements | B18: =IFERROR(SUMIFS(AllItems!$I$2:$I$77,AllItems!$A$2:$A$77,"License Optimization",AllItems!$C$2:$C$77,A18)/SUMIFS(AllItems!$H$2:$H$77,AllItems!$A$2:$A$77,"License Optimization",AllItems!$C$2:$C$77,A18),"") | C18: =IF(B18="","",B18/4) | D18: =IF(B18="","Not assessed",INDEX(Lists!$B$2:$B$6,MIN(5,INT(B18)+1)))
A19: Deployment & Usage | B19: =IFERROR(SUMIFS(AllItems!$I$2:$I$77,AllItems!$A$2:$A$77,"License Optimization",AllItems!$C$2:$C$77,A19)/SUMIFS(AllItems!$H$2:$H$77,AllItems!$A$2:$A$77,"License Optimization",AllItems!$C$2:$C$77,A19),"") | C19: =IF(B19="","",B19/4) | D19: =IF(B19="","Not assessed",INDEX(Lists!$B$2:$B$6,MIN(5,INT(B19)+1)))
A20: Security Value Realization | B20: =IFERROR(SUMIFS(AllItems!$I$2:$I$77,AllItems!$A$2:$A$77,"License Optimization",AllItems!$C$2:$C$77,A20)/SUMIFS(AllItems!$H$2:$H$77,AllItems!$A$2:$A$77,"License Optimization",AllItems!$C$2:$C$77,A20),"") | C20: =IF(B20="","",B20/4) | D20: =IF(B20="","Not assessed",INDEX(Lists!$B$2:$B$6,MIN(5,INT(B20)+1)))
A21: Cloud Cost | B21: =IFERROR(SUMIFS(AllItems!$I$2:$I$77,AllItems!$A$2:$A$77,"License Optimization",AllItems!$C$2:$C$77,A21)/SUMIFS(AllItems!$H$2:$H$77,AllItems!$A$2:$A$77,"License Optimization",AllItems!$C$2:$C$77,A21),"") | C21: =IF(B21="","",B21/4) | D21: =IF(B21="","Not assessed",INDEX(Lists!$B$2:$B$6,MIN(5,INT(B21)+1)))
A22: Programs & Negotiation | B22: =IFERROR(SUMIFS(AllItems!$I$2:$I$77,AllItems!$A$2:$A$77,"License Optimization",AllItems!$C$2:$C$77,A22)/SUMIFS(AllItems!$H$2:$H$77,AllItems!$A$2:$A$77,"License Optimization",AllItems!$C$2:$C$77,A22),"") | C22: =IF(B22="","",B22/4) | D22: =IF(B22="","Not assessed",INDEX(Lists!$B$2:$B$6,MIN(5,INT(B22)+1)))
A25: App Modernization — by dimension
A26: Dimension | B26: Score (0–4) | C26: Score % | D26: Maturity level
A27: Portfolio Visibility | B27: =IFERROR(SUMIFS(AllItems!$I$2:$I$77,AllItems!$A$2:$A$77,"App Modernization",AllItems!$C$2:$C$77,A27)/SUMIFS(AllItems!$H$2:$H$77,AllItems!$A$2:$A$77,"App Modernization",AllItems!$C$2:$C$77,A27),"") | C27: =IF(B27="","",B27/4) | D27: =IF(B27="","Not assessed",INDEX(Lists!$B$2:$B$6,MIN(5,INT(B27)+1)))
A28: Lifecycle & Supportability | B28: =IFERROR(SUMIFS(AllItems!$I$2:$I$77,AllItems!$A$2:$A$77,"App Modernization",AllItems!$C$2:$C$77,A28)/SUMIFS(AllItems!$H$2:$H$77,AllItems!$A$2:$A$77,"App Modernization",AllItems!$C$2:$C$77,A28),"") | C28: =IF(B28="","",B28/4) | D28: =IF(B28="","Not assessed",INDEX(Lists!$B$2:$B$6,MIN(5,INT(B28)+1)))
A29: Rationalization & Roadmap | B29: =IFERROR(SUMIFS(AllItems!$I$2:$I$77,AllItems!$A$2:$A$77,"App Modernization",AllItems!$C$2:$C$77,A29)/SUMIFS(AllItems!$H$2:$H$77,AllItems!$A$2:$A$77,"App Modernization",AllItems!$C$2:$C$77,A29),"") | C29: =IF(B29="","",B29/4) | D29: =IF(B29="","Not assessed",INDEX(Lists!$B$2:$B$6,MIN(5,INT(B29)+1)))
A30: Engineering & Release | B30: =IFERROR(SUMIFS(AllItems!$I$2:$I$77,AllItems!$A$2:$A$77,"App Modernization",AllItems!$C$2:$C$77,A30)/SUMIFS(AllItems!$H$2:$H$77,AllItems!$A$2:$A$77,"App Modernization",AllItems!$C$2:$C$77,A30),"") | C30: =IF(B30="","",B30/4) | D30: =IF(B30="","Not assessed",INDEX(Lists!$B$2:$B$6,MIN(5,INT(B30)+1)))
A31: Resilience & Recovery | B31: =IFERROR(SUMIFS(AllItems!$I$2:$I$77,AllItems!$A$2:$A$77,"App Modernization",AllItems!$C$2:$C$77,A31)/SUMIFS(AllItems!$H$2:$H$77,AllItems!$A$2:$A$77,"App Modernization",AllItems!$C$2:$C$77,A31),"") | C31: =IF(B31="","",B31/4) | D31: =IF(B31="","Not assessed",INDEX(Lists!$B$2:$B$6,MIN(5,INT(B31)+1)))
A32: Cloud & Data Readiness | B32: =IFERROR(SUMIFS(AllItems!$I$2:$I$77,AllItems!$A$2:$A$77,"App Modernization",AllItems!$C$2:$C$77,A32)/SUMIFS(AllItems!$H$2:$H$77,AllItems!$A$2:$A$77,"App Modernization",AllItems!$C$2:$C$77,A32),"") | C32: =IF(B32="","",B32/4) | D32: =IF(B32="","Not assessed",INDEX(Lists!$B$2:$B$6,MIN(5,INT(B32)+1)))
A35: Zero Trust — by dimension
A36: Dimension | B36: Score (0–4) | C36: Score % | D36: Maturity level
A37: Identity | B37: =IFERROR(SUMIFS(AllItems!$I$2:$I$77,AllItems!$A$2:$A$77,"Zero Trust",AllItems!$C$2:$C$77,A37)/SUMIFS(AllItems!$H$2:$H$77,AllItems!$A$2:$A$77,"Zero Trust",AllItems!$C$2:$C$77,A37),"") | C37: =IF(B37="","",B37/4) | D37: =IF(B37="","Not assessed",INDEX(Lists!$B$2:$B$6,MIN(5,INT(B37)+1)))
A38: Devices | B38: =IFERROR(SUMIFS(AllItems!$I$2:$I$77,AllItems!$A$2:$A$77,"Zero Trust",AllItems!$C$2:$C$77,A38)/SUMIFS(AllItems!$H$2:$H$77,AllItems!$A$2:$A$77,"Zero Trust",AllItems!$C$2:$C$77,A38),"") | C38: =IF(B38="","",B38/4) | D38: =IF(B38="","Not assessed",INDEX(Lists!$B$2:$B$6,MIN(5,INT(B38)+1)))
A39: Networks | B39: =IFERROR(SUMIFS(AllItems!$I$2:$I$77,AllItems!$A$2:$A$77,"Zero Trust",AllItems!$C$2:$C$77,A39)/SUMIFS(AllItems!$H$2:$H$77,AllItems!$A$2:$A$77,"Zero Trust",AllItems!$C$2:$C$77,A39),"") | C39: =IF(B39="","",B39/4) | D39: =IF(B39="","Not assessed",INDEX(Lists!$B$2:$B$6,MIN(5,INT(B39)+1)))
A40: Applications & Workloads | B40: =IFERROR(SUMIFS(AllItems!$I$2:$I$77,AllItems!$A$2:$A$77,"Zero Trust",AllItems!$C$2:$C$77,A40)/SUMIFS(AllItems!$H$2:$H$77,AllItems!$A$2:$A$77,"Zero Trust",AllItems!$C$2:$C$77,A40),"") | C40: =IF(B40="","",B40/4) | D40: =IF(B40="","Not assessed",INDEX(Lists!$B$2:$B$6,MIN(5,INT(B40)+1)))
A41: Data | B41: =IFERROR(SUMIFS(AllItems!$I$2:$I$77,AllItems!$A$2:$A$77,"Zero Trust",AllItems!$C$2:$C$77,A41)/SUMIFS(AllItems!$H$2:$H$77,AllItems!$A$2:$A$77,"Zero Trust",AllItems!$C$2:$C$77,A41),"") | C41: =IF(B41="","",B41/4) | D41: =IF(B41="","Not assessed",INDEX(Lists!$B$2:$B$6,MIN(5,INT(B41)+1)))
A42: Visibility & Analytics | B42: =IFERROR(SUMIFS(AllItems!$I$2:$I$77,AllItems!$A$2:$A$77,"Zero Trust",AllItems!$C$2:$C$77,A42)/SUMIFS(AllItems!$H$2:$H$77,AllItems!$A$2:$A$77,"Zero Trust",AllItems!$C$2:$C$77,A42),"") | C42: =IF(B42="","",B42/4) | D42: =IF(B42="","Not assessed",INDEX(Lists!$B$2:$B$6,MIN(5,INT(B42)+1)))
A43: Governance & Readiness | B43: =IFERROR(SUMIFS(AllItems!$I$2:$I$77,AllItems!$A$2:$A$77,"Zero Trust",AllItems!$C$2:$C$77,A43)/SUMIFS(AllItems!$H$2:$H$77,AllItems!$A$2:$A$77,"Zero Trust",AllItems!$C$2:$C$77,A43),"") | C43: =IF(B43="","",B43/4) | D43: =IF(B43="","Not assessed",INDEX(Lists!$B$2:$B$6,MIN(5,INT(B43)+1)))

Sheet Priority Gaps
A1: Priority Gaps
A2: The 20 answered items with the most gap points ((4 − score) × weight). Updates automatically.
A4: Rank | B4: Service | C4: ID | D4: Dimension | E4: Question | F4: Score | G4: Weight | H4: Gap points | I4: Recommended action | J4: HHS CPG mapping | K4: Key | L4: Row
